Workbook

Sheet EXAMPLE-PRODUCT & VOLUME
C5: BRAND | F5: This page is for all your basic information. If you have more than one SKU, please fill in up to 6 SKU's. If you need to do more for your own records, it will be easiest to do multiple workbooks. The fields in yellow are to be filled in, other cells will self calculate and feed through the document. Please hover your curser over the red triangle when in a cell, this will provide more information on what is required.
C6: Big Hens Inedible Chicken Delights
C8: NUMBER OF SKU's (to be assessed in this workbook)
C9: 2
C11: CATEGORY | D11: AISLE
C12: Meal Solutions | D12: Freezer
C14: SHELF LIFE
C15: 18 | D15: Months
E17: UNITS | F17: TOTAL VOL | G17: OF WHICH | H17: OF WHICH | I17: OF WHICH | L17: UNIT | M17: KG
C18: PRODUCTS | D18: PACK SIZE | E18: CARTON | F18: UNITS | G18: WOOLWORTHS | H18: OTHER RETAIL | I18: OTHER | J18: RRP | K18: GST | L18: PRICING | M18: PER YEAR
B19: 1. | C19: Chicken Lip Nuggets | D19: 0.34 | E19: 6 | F19: 40000 | G19: 4500 | H19: 25000 | I19: =F19-G19-H19 -> 10500 | J19: 11.95 | K19: YES | L19: =IFERROR((J19/D19),"") -> 35.147059 | M19: =F19*D19 -> 13600
B20: 2. | C20: Chicken Feather Soup | D20: 0.4 | E20: 6 | F20: 6500 | G20: 0 | H20: 2250 | I20: =F20-G20-H20 -> 4250 | J20: 9.95 | K20: NO | L20: =IFERROR((J20/D20),"") -> 24.875 | M20: =F20*D20 -> 2600
B21: 3. | L21: =IFERROR((J21/D21),"") | M21: =F21*D21 -> 0
B22: 4. | L22: =IFERROR((J22/D22),"") | M22: =F22*D22 -> 0
B23: 5. | L23: =IFERROR((J23/D23),"") | M23: =F23*D23 -> 0
B24: 6. | L24: =IFERROR((J24/D24),"") | M24: =F24*D24 -> 0
C25: Total Units | F25: =SUM(F19:F24) -> 46500 | G25: =SUM(G19:G24) -> 4500 | H25: =SUM(H19:H24) -> 27250 | I25: =SUM(I19:I24) -> 14750 | M25: =SUM(M19:M24) -> 16200
C26: Percentage split (balance) | F26: =F25/$F$25 -> 1 | G26: =G25/$F$25 -> 0.096774194 | H26: =H25/$F$25 -> 0.58602151 | I26: =I25/$F$25 -> 0.3172043
C28: RANGING
C29: WOOLWORTHS STORES | D29: 45 | E29: =IFERROR((G25/52)/D29,"") -> 1.9230769 | F29: UPSPW
C30: OTHER RETAIL (INDIES / COLES) | D30: 360 | E30: =IFERROR((H25/52)/D30,"") -> 1.4556624 | F30: UPSPW
C31: OTHER / MARKETS / E-COM | D31: ----- | E31: =I25/52 -> 283.65385 | F31: UPW

Sheet EXAMPLE-COSTING SKU
B2: *** This sheet is confidential, please use this to obtain your product cost, but do not share the document. Please print the 'Products & Volume' sheet and the 'Analysis' sheets as a PDF file for the Seedlab team to review ***
B3: Seedlab team members do not need this level of information unless working with you on reducing costs in a private mentor session
B5: PRODUCT | E5: DECLARED WT. | G5: AV. ACTUAL WT. | I5: GIVE AWAY %
B6: ='EXAMPLE-PRODUCT & VOLUME'!C19 -> Chicken Lip Nuggets | E6: ='EXAMPLE-PRODUCT & VOLUME'!D19 -> 0.34 | G6: =E6*102.5% -> 0.3485 | I6: =(E6-G6)/E6 -> -0.025
B8: Ingredients - Batch | H8: KG | I8: % | J8: YIELD | K8: COST/KG | L8: INPUT KG | M8: COST / BATCH
B9: 1 | C9: Chicken Lips | H9: 200 | I9: =IFERROR(IF(H9/$H$29=0,"",H9/$H$29),"") -> 0.77417357 | J9: 1 | K9: 9.25 | L9: =IFERROR(H9/J9,"") -> 200 | M9: =IFERROR(L9*K9,"") -> 1850
B10: 2 | C10: Tapioca Starch | H10: 15 | I10: =IFERROR(IF(H10/$H$29=0,"",H10/$H$29),"") -> 0.058063018 | J10: 1 | K10: 2.15 | L10: =IFERROR(H10/J10,"") -> 15 | M10: =IFERROR(L10*K10,"") -> 32.25
B11: 3 | C11: Garlic Powder | H11: 0.08 | I11: =IFERROR(IF(H11/$H$29=0,"",H11/$H$29),"") -> 0.00030966943 | J11: 1 | K11: 26 | L11: =IFERROR(H11/J11,"") -> 0.08 | M11: =IFERROR(L11*K11,"") -> 2.08
B12: 4 | C12: Carrot - Grated | H12: 4 | I12: =IFERROR(IF(H12/$H$29=0,"",H12/$H$29),"") -> 0.015483471 | J12: 0.88 | K12: 0.72 | L12: =IFERROR(H12/J12,"") -> 4.5454545 | M12: =IFERROR(L12*K12,"") -> 3.2727273
B13: 5 | C13: Onion Powder | H13: 0.04 | I13: =IFERROR(IF(H13/$H$29=0,"",H13/$H$29),"") -> 0.00015483471 | J13: 1 | K13: 22.5 | L13: =IFERROR(H13/J13,"") -> 0.04 | M13: =IFERROR(L13*K13,"") -> 0.9
B14: 6 | C14: Salt | H14: 0.015 | I14: =IFERROR(IF(H14/$H$29=0,"",H14/$H$29),"") -> 5.8063018e-05 | J14: 1 | K14: 0.98 | L14: =IFERROR(H14/J14,"") -> 0.015 | M14: =IFERROR(L14*K14,"") -> 0.0147
B15: 7 | C15: White Pepper | H15: 0.005 | I15: =IFERROR(IF(H15/$H$29=0,"",H15/$H$29),"") -> 1.9354339e-05 | J15: 1 | K15: 19.85 | L15: =IFERROR(H15/J15,"") -> 0.005 | M15: =IFERROR(L15*K15,"") -> 0.09925
B16: 8 | C16: Batter Premix | H16: 5.2 | I16: =IFERROR(IF(H16/$H$29=0,"",H16/$H$29),"") -> 0.020128513 | J16: 0.8 | K16: 8.95 | L16: =IFERROR(H16/J16,"") -> 6.5 | M16: =IFERROR(L16*K16,"") -> 58.175
B17: 9 | C17: Water | H17: 10 | I17: =IFERROR(IF(H17/$H$29=0,"",H17/$H$29),"") -> 0.038708678 | J17: 1 | K17: 0 | L17: =IFERROR(H17/J17,"") -> 10 | M17: =IFERROR(L17*K17,"") -> 0
B18: 10 | C18: Panko Crumbs | H18: 18 | I18: =IFERROR(IF(H18/$H$29=0,"",H18/$H$29),"") -> 0.069675621 | J18: 0.75 | K18: 12.65 | L18: =IFERROR(H18/J18,"") -> 24 | M18: =IFERROR(L18*K18,"") -> 303.6
B19: 11 | C19: Oil | H19: 6 | I19: =IFERROR(IF(H19/$H$29=0,"",H19/$H$29),"") -> 0.023225207 | J19: 1 | K19: 1.95 | L19: =IFERROR(H19/J19,"") -> 6 | M19: =IFERROR(L19*K19,"") -> 11.7
B20: 12 | I20: =IFERROR(IF(H20/$H$29=0,"",H20/$H$29),"") | L20: =IFERROR(H20/J20,"") | M20: =IFERROR(L20*K20,"")
B21: 13 | I21: =IFERROR(IF(H21/$H$29=0,"",H21/$H$29),"") | L21: =IFERROR(H21/J21,"") | M21: =IFERROR(L21*K21,"")
B22: 14 | I22: =IFERROR(IF(H22/$H$29=0,"",H22/$H$29),"") | L22: =IFERROR(H22/J22,"") | M22: =IFERROR(L22*K22,"")
B23: 15 | I23: =IFERROR(IF(H23/$H$29=0,"",H23/$H$29),"") | L23: =IFERROR(H23/J23,"") | M23: =IFERROR(L23*K23,"")
B24: 16 | I24: =IFERROR(IF(H24/$H$29=0,"",H24/$H$29),"") | L24: =IFERROR(H24/J24,"") | M24: =IFERROR(L24*K24,"")
B25: 17 | I25: =IFERROR(IF(H25/$H$29=0,"",H25/$H$29),"") | L25: =IFERROR(H25/J25,"") | M25: =IFERROR(L25*K25,"")
B26: 18 | I26: =IFERROR(IF(H26/$H$29=0,"",H26/$H$29),"") | L26: =IFERROR(H26/J26,"") | M26: =IFERROR(L26*K26,"")
B27: 19 | I27: =IFERROR(IF(H27/$H$29=0,"",H27/$H$29),"") | L27: =IFERROR(H27/J27,"") | M27: =IFERROR(L27*K27,"")
B28: 20 | I28: =IFERROR(IF(H28/$H$29=0,"",H28/$H$29),"") | L28: =IFERROR(H28/J28,"") | M28: =IFERROR(L28*K28,"")
B29: Total | H29: =SUM(H9:H28) -> 258.34 | I29: =SUM(I9:I28) -> 1 | L29: =SUM(L9:L28) -> 266.18545 | M29: =SUM(M9:M28) -> 2262.0917
B31: Packaging - Batch | H31: EA | I31: COST/EA | J31: COST/EA
B32: 1 | C32: Pre-Printed Pouch | H32: =H29/G6 -> 741.29125 | I32: 0.49 | J32: =H32*I32 -> 363.23271
B33: 2 | C33: Carton / Shelf Ready (6's) | H33: =H32/G62 -> 123.54854 | I33: 1.25 | J33: =H33*I33 -> 154.43568
B34: 3 | J34: =H34*I34 -> 0
B35: 4 | J35: =H35*I35 -> 0
B36: TOTAL BATCH PACKAGING | J36: =SUM(J32:J35) -> 517.66839
B39: Direct Labour - Batch (includes super, entitlements & work cover) | H39: HEADS | I39: HOURS | J39: RATE/Hr | K39: COST/EA
B40: 1 | C40: Casual Staff | H40: 2 | I40: 8 | J40: 34.93 | K40: =H40*I40*J40 -> 558.88
B41: 2 | C41: Full Time | H41: 0 | I41: 8 | J41: 32.48 | K41: =H41*I41*J41 -> 0
B42: TOTAL BATCH WAGES | K42: =SUM(K40:K41) -> 558.88
B44: Total Kilos P/A (As in Sheet 1) | G44: ='EXAMPLE-PRODUCT & VOLUME'!M25 -> 16200
B45: Overheads - Batch (total annual cost / kg per annum) | I45: ANNUAL | J45: KG/YEAR
B46: 1 | C46: Electricity | I46: 4000 | J46: =I46/$G$44 -> 0.24691358
B47: 2 | C47: Water | I47: 1200 | J47: =I47/$G$44 -> 0.074074074
...

Sheet EXAMPLE-ANALYSIS
B3: 1. | C3: PRODUCT PRICING REVIEW
D5: PACK | F5: UNIT | H5: EX | J5: RSP | L5: Unit Price | O5: Standard | P5: Deep Cut | Q5: Promotion
C6: PRODUCTS | D6: SIZE | E6: RRP | F6: PRICING | G6: GST | H6: GST | J6: Difference | L6: Difference | O6: Promotion | P6: Promotion | Q6: Frequency
C7: ='EXAMPLE-PRODUCT & VOLUME'!C19 -> Chicken Lip Nuggets | D7: ='EXAMPLE-PRODUCT & VOLUME'!D19 -> 0.34 | E7: ='EXAMPLE-PRODUCT & VOLUME'!J19 -> 11.95 | F7: ='EXAMPLE-PRODUCT & VOLUME'!L19 -> 35.147059 | G7: ='EXAMPLE-PRODUCT & VOLUME'!K19 -> YES | H7: =IF(G7="YES",(E7/110%),E7) -> 10.863636 | O7: 0.2 | P7: 0.25 | Q7: Monthly
C8: Nearest Competitor (Woolworths) | D8: 0.3 | E8: 11 | F8: =E8/D8 -> 36.666667 | G8: YES | H8: =IF(G8="YES",(E8/110%),E8) -> 10 | J8: =E7-E8 -> 0.95 | K8: =(E7-E8)/E7 -> 0.079497908 | L8: =F7-F8 -> -1.5196078 | M8: =(F7-F8)/F7 -> -0.043235704 | O8: 0.2 | P8: 0.5 | Q8: Monthly
C9: Cheapest Competitor (Woolworths) | D9: 0.28 | E9: 9 | F9: =E9/D9 -> 32.142857 | G9: YES | H9: =IF(G9="YES",(E9/110%),E9) -> 8.1818182 | J9: =E7-E9 -> 2.95 | K9: =(E7-E9)/E8 -> 0.26818182 | L9: =F7-F9 -> 3.0042017 | M9: =(F7-F9)/F8 -> 0.081932773 | O9: 0.2 | P9: 0.3 | Q9: Fortnightly
C11: CUSTOMER MARGIN REVIEW | D11: Woolworths | E11: Other Retail (Average) | F11: Other (Direct To Customer) | H11: Notes on this product:
B12: TOP DOWN | C12: Retailer Actual Sell Price | D12: 11.95 | E12: 13 | F12: 11.95
C13: Retailer / Consumer Buy Price | D13: 7.5 | E13: 8.2 | F13: 11.95
C14: Rebates (Collective) | D14: 0.39 | E14: 0.26 | F14: 0
C15: Retailer Net Buy Price | D15: =D13-D14 -> 7.11 | E15: =E13-E14 -> 7.94 | F15: =F13-F14 -> 11.95
C16: Retailer Margin | D16: =(D12-D15)/D12 -> 0.40502092 | E16: =(E12-E15)/E12 -> 0.38923077 | F16: N/A
C18: Category Expectations | D18: 0.48 | E18: 0.6
C19: Gap % | D19: =D16-D18 -> -0.074979079 | E19: =E16-E18 -> -0.21076923
C20: Gap $ | D20: =(D15*D18)-(D15*D16) -> 0.53310126 | E20: =(E15*E18)-(E15*E16) -> 1.6735077
B22: BOTTOM UP | C22: Target Sell Price | D22: =D15-D20 -> 6.5768987 | E22: =E15-E20 -> 6.2664923 | H22: QUESTIONS FOR CONSIDERATION:
C23: New Margin $ | D23: =D22-D28 -> 1.2749738 | E23: =E22-E28 -> 0.96456736 | H23: On comparing your RSP & Unit Pricing, is an adjustment required for this product in order to be competitive?
C24: New Margin % | D24: =(D22-D28)/D22 -> 0.19385638 | E24: =(E22-E28)/E22 -> 0.15392461 | H24: If so, what does this do to your margins?
H25: Where can savings be made to COGS? Consider big wins first.
C26: Current Margin % | D26: =(D15-D28)/D15 -> 0.25430029 | E26: =(E15-E28)/E15 -> 0.33225127 | F26: =(F13-F28)/F13 -> 0.55632427 | H26: If your overheads make your product non-proffitable, what needs to happen to change it?
C27: Current Margin $ | D27: =D15-D28 -> 1.8080751 | E27: =E15-E28 -> 2.6380751 | F27: =F13-F28 -> 6.6480751 | H27: What are the risks associated with your current distribution / sales spread?
C28: Current Cost | D28: ='EXAMPLE-COSTING SKU'!I61 -> 5.3019249 | E28: =D28 -> 5.3019249 | F28: =E28 -> 5.3019249
C30: Current Volume | D30: ='EXAMPLE-PRODUCT & VOLUME'!G19 -> 4500 | E30: ='EXAMPLE-PRODUCT & VOLUME'!H19 -> 25000 | F30: ='EXAMPLE-PRODUCT & VOLUME'!I19 -> 10500
C31: Current Value | D31: =D30*D15 -> 31995 | E31: =E30*E15 -> 198500 | F31: =F30*F15 -> 125475

Sheet PRODUCTS & VOLUME
A1: ProductVol
C2: Once complete, please click the PRINT button and save as PDF for sharing with the Seedlab team.
C9: BRAND | F9: Please provide any notes you wish to share with the Seedlab Team:
C12: NUMBER OF SKU's (to be assessed in this workbook)
C15: CATEGORY | D15: AISLE
C18: SHELF LIFE
E21: UNITS | F21: TOTAL VOL | G21: OF WHICH | H21: OF WHICH | I21: OF WHICH | L21: UNIT | M21: KG
C22: PRODUCTS | D22: PACK SIZE | E22: CARTON | F22: UNITS | G22: WOOLWORTHS | H22: OTHER RETAIL | I22: OTHER | J22: RRP | K22: GST | L22: PRICING | M22: PER YEAR
B23: 1. | L23: =IFERROR((J23/D23),"") | M23: =F23*D23 -> 0
B24: 2. | L24: =IFERROR((J24/D24),"") | M24: =F24*D24 -> 0
B25: 3. | L25: =IFERROR((J25/D25),"") | M25: =F25*D25 -> 0
B26: 4. | L26: =IFERROR((J26/D26),"") | M26: =F26*D26 -> 0
B27: 5. | L27: =IFERROR((J27/D27),"") | M27: =F27*D27 -> 0
B28: 6. | L28: =IFERROR((J28/D28),"") | M28: =F28*D28 -> 0
C29: Total Units | F29: =SUM(F23:F28) -> 0 | G29: =SUM(G23:G28) -> 0 | H29: =SUM(H23:H28) -> 0 | I29: =SUM(I23:I28) -> 0 | M29: =SUM(M23:M28) -> 0
C30: Percentage split (balance) | F30: =IFERROR(F29/$F$29,"") | G30: =IFERROR(G29/$F$29,"") | H30: =IFERROR(H29/$F$29,"") | I30: =IFERROR(I29/$F$29,"")
C32: RANGING
C33: WOOLWORTHS STORES | E33: =IFERROR((G29/52)/D33,"") | F33: UPSPW
C34: OTHER RETAIL (INDIES / COLES) | E34: =IFERROR((H29/52)/D34,"") | F34: UPSPW
C35: OTHER / MARKETS / E-COM | D35: ----- | E35: =I29/52 -> 0 | F35: UPW

Sheet COSTING SKU 1
B2: *** This sheet is confidential, please use this to obtain your product cost, but do not share the document. Please print the 'Products & Volume' sheet and the 'Analysis' sheets as a PDF file for the Seedlab team to review ***
B3: Seedlab team members do not need this level of information unless working with you on reducing costs in a private mentor session
B5: PRODUCT | E5: DECLARED WT. | G5: AV. ACTUAL WT. | I5: GIVE AWAY %
B6: ='PRODUCTS & VOLUME'!C23 -> 0 | E6: ='PRODUCTS & VOLUME'!D23 -> 0 | G6: =E6*102.5% -> 0 | I6: =IFERROR((E6-G6)/E6,"")
B8: Ingredients - Batch | H8: KG | I8: % | J8: YIELD | K8: COST/KG | L8: INPUT KG | M8: COST / BATCH
B9: 1 | I9: =IFERROR(IF(H9/$H$29=0,"",H9/$H$29),"") | L9: =IFERROR(H9/J9,"") | M9: =IFERROR(L9*K9,"")
B10: 2 | I10: =IFERROR(IF(H10/$H$29=0,"",H10/$H$29),"") | L10: =IFERROR(H10/J10,"") | M10: =IFERROR(L10*K10,"")
B11: 3 | I11: =IFERROR(IF(H11/$H$29=0,"",H11/$H$29),"") | L11: =IFERROR(H11/J11,"") | M11: =IFERROR(L11*K11,"")
B12: 4 | I12: =IFERROR(IF(H12/$H$29=0,"",H12/$H$29),"") | L12: =IFERROR(H12/J12,"") | M12: =IFERROR(L12*K12,"")
B13: 5 | I13: =IFERROR(IF(H13/$H$29=0,"",H13/$H$29),"") | L13: =IFERROR(H13/J13,"") | M13: =IFERROR(L13*K13,"")
B14: 6 | I14: =IFERROR(IF(H14/$H$29=0,"",H14/$H$29),"") | L14: =IFERROR(H14/J14,"") | M14: =IFERROR(L14*K14,"")
B15: 7 | I15: =IFERROR(IF(H15/$H$29=0,"",H15/$H$29),"") | L15: =IFERROR(H15/J15,"") | M15: =IFERROR(L15*K15,"")
B16: 8 | I16: =IFERROR(IF(H16/$H$29=0,"",H16/$H$29),"") | L16: =IFERROR(H16/J16,"") | M16: =IFERROR(L16*K16,"")
B17: 9 | I17: =IFERROR(IF(H17/$H$29=0,"",H17/$H$29),"") | L17: =IFERROR(H17/J17,"") | M17: =IFERROR(L17*K17,"")
B18: 10 | I18: =IFERROR(IF(H18/$H$29=0,"",H18/$H$29),"") | L18: =IFERROR(H18/J18,"") | M18: =IFERROR(L18*K18,"")
B19: 11 | I19: =IFERROR(IF(H19/$H$29=0,"",H19/$H$29),"") | L19: =IFERROR(H19/J19,"") | M19: =IFERROR(L19*K19,"")
B20: 12 | I20: =IFERROR(IF(H20/$H$29=0,"",H20/$H$29),"") | L20: =IFERROR(H20/J20,"") | M20: =IFERROR(L20*K20,"")
... B28: 20 | I28: =IFERROR(IF(H28/$H$29=0,"",H28/$H$29),"") | L28: =IFERROR(H28/J28,"") | M28: =IFERROR(L28*K28,"")
B29: Total | H29: =SUM(H9:H28) -> 0 | I29: =SUM(I9:I28) -> 0 | L29: =SUM(L9:L28) -> 0 | M29: =SUM(M9:M28) -> 0
B31: Packaging - Batch | H31: EA REQ. | I31: COST/EA | J31: COST/Batch
B32: 1 | J32: =IFERROR(H32*I32,"") -> 0
B33: 2 | J33: =IFERROR(H33*I33,"") -> 0
B34: 3 | J34: =IFERROR(H34*I34,"") -> 0
B35: 4 | J35: =IFERROR(H35*I35,"") -> 0
B36: TOTAL BATCH PACKAGING | J36: =SUM(J32:J35) -> 0
B39: Direct Labour - Batch (includes super, entitlements & work cover) | H39: HEADS | I39: HOURS | J39: RATE/Hr | K39: COST/Batch
B40: 1 | C40: Casual Staff | K40: =H40*I40*J40 -> 0
B41: 2 | C41: Full Time | K41: =H41*I41*J41 -> 0
B42: TOTAL BATCH WAGES | K42: =SUM(K40:K41) -> 0
B44: Total Kilos P/A (As in Sheet 1) | G44: ='PRODUCTS & VOLUME'!$M$29 -> 0
B45: Overheads - Batch (total annual cost / kg per annum) | I45: ANNUAL | J45: KG/YEAR
B46: 1 | C46: Electricity | J46: =IFERROR(I46/$G$44,"")
B47: 2 | C47: Water | J47: =IFERROR(I47/$G$44,"")
B48: 3 | C48: Rent / Warehousing | J48: =IFERROR(I48/$G$44,"")
B49: 4 | C49: Full Time Admin & Other Staff (incl owners if not included in production) | J49: =IFERROR(I49/$G$44,"")
B50: 5 | C50: Office Supplies | J50: =IFERROR(I50/$G$44,"")
B51: 6 | C51: Production Consumables (gloves, pallet wrap etc) | J51: =IFERROR(I51/$G$44,"")
B52: 7 | C52: Insurance | J52: =IFERROR(I52/$G$44,"")
B53: 8 | C53: Audit Costs | J53: =IFERROR(I53/$G$44,"")
B54: 9 | C54: Certifications | J54: =IFERROR(I54/$G$44,"")
...

Sheet COSTING SKU 2
B2: *** This sheet is confidential, please use this to obtain your product cost, but do not share the document. Please print the 'Products & Volume' sheet and the 'Analysis' sheets as a PDF file for the Seedlab team to review ***
B3: Seedlab team members do not need this level of information unless working with you on reducing costs in a private mentor session
B5: PRODUCT | E5: DECLARED WT. | G5: AV. ACTUAL WT. | I5: GIVE AWAY %
B6: ='PRODUCTS & VOLUME'!C24 -> 0 | E6: ='PRODUCTS & VOLUME'!D24 -> 0 | G6: =E6*102.5% -> 0 | I6: =IFERROR((E6-G6)/E6,"")
B8: Ingredients - Batch | H8: KG | I8: % | J8: YIELD | K8: COST/KG | L8: INPUT KG | M8: COST / BATCH
B9: 1 | I9: =IFERROR(IF(H9/$H$29=0,"",H9/$H$29),"") | L9: =IFERROR(H9/J9,"") | M9: =IFERROR(L9*K9,"")
B10: 2 | I10: =IFERROR(IF(H10/$H$29=0,"",H10/$H$29),"") | L10: =IFERROR(H10/J10,"") | M10: =IFERROR(L10*K10,"")
B11: 3 | I11: =IFERROR(IF(H11/$H$29=0,"",H11/$H$29),"") | L11: =IFERROR(H11/J11,"") | M11: =IFERROR(L11*K11,"")
B12: 4 | I12: =IFERROR(IF(H12/$H$29=0,"",H12/$H$29),"") | L12: =IFERROR(H12/J12,"") | M12: =IFERROR(L12*K12,"")
B13: 5 | I13: =IFERROR(IF(H13/$H$29=0,"",H13/$H$29),"") | L13: =IFERROR(H13/J13,"") | M13: =IFERROR(L13*K13,"")
B14: 6 | I14: =IFERROR(IF(H14/$H$29=0,"",H14/$H$29),"") | L14: =IFERROR(H14/J14,"") | M14: =IFERROR(L14*K14,"")
B15: 7 | I15: =IFERROR(IF(H15/$H$29=0,"",H15/$H$29),"") | L15: =IFERROR(H15/J15,"") | M15: =IFERROR(L15*K15,"")
B16: 8 | I16: =IFERROR(IF(H16/$H$29=0,"",H16/$H$29),"") | L16: =IFERROR(H16/J16,"") | M16: =IFERROR(L16*K16,"")
B17: 9 | I17: =IFERROR(IF(H17/$H$29=0,"",H17/$H$29),"") | L17: =IFERROR(H17/J17,"") | M17: =IFERROR(L17*K17,"")
B18: 10 | I18: =IFERROR(IF(H18/$H$29=0,"",H18/$H$29),"") | L18: =IFERROR(H18/J18,"") | M18: =IFERROR(L18*K18,"")
B19: 11 | I19: =IFERROR(IF(H19/$H$29=0,"",H19/$H$29),"") | L19: =IFERROR(H19/J19,"") | M19: =IFERROR(L19*K19,"")
B20: 12 | I20: =IFERROR(IF(H20/$H$29=0,"",H20/$H$29),"") | L20: =IFERROR(H20/J20,"") | M20: =IFERROR(L20*K20,"")
... B28: 20 | I28: =IFERROR(IF(H28/$H$29=0,"",H28/$H$29),"") | L28: =IFERROR(H28/J28,"") | M28: =IFERROR(L28*K28,"")
B29: Total | H29: =SUM(H9:H28) -> 0 | I29: =SUM(I9:I28) -> 0 | L29: =SUM(L9:L28) -> 0 | M29: =SUM(M9:M28) -> 0
B31: Packaging - Batch | H31: EA REQ. | I31: COST/EA | J31: COST/Batch
B32: 1 | J32: =IFERROR(H32*I32,"") -> 0
B33: 2 | J33: =IFERROR(H33*I33,"") -> 0
B34: 3 | J34: =IFERROR(H34*I34,"") -> 0
B35: 4 | J35: =IFERROR(H35*I35,"") -> 0
B36: TOTAL BATCH PACKAGING | J36: =SUM(J32:J35) -> 0
B39: Direct Labour - Batch (includes super, entitlements & work cover) | H39: HEADS | I39: HOURS | J39: RATE/Hr | K39: COST/Batch
B40: 1 | C40: Casual Staff | K40: =H40*I40*J40 -> 0
B41: 2 | C41: Full Time | K41: =H41*I41*J41 -> 0
B42: TOTAL BATCH WAGES | K42: =SUM(K40:K41) -> 0
B44: Total Kilos P/A (As in Sheet 1) | G44: ='PRODUCTS & VOLUME'!M29 -> 0
B45: Overheads - Batch (total annual cost / kg per annum) | I45: ANNUAL | J45: KG/YEAR
B46: 1 | C46: Electricity | J46: =IFERROR(I46/$G$44,"")
B47: 2 | C47: Water | J47: =IFERROR(I47/$G$44,"")
B48: 3 | C48: Rent / Warehousing | J48: =IFERROR(I48/$G$44,"")
B49: 4 | C49: Full Time Admin & Other Staff (incl owners if not included in production) | J49: =IFERROR(I49/$G$44,"")
B50: 5 | C50: Office Supplies | J50: =IFERROR(I50/$G$44,"")
B51: 6 | C51: Production Consumables (gloves, pallet wrap etc) | J51: =IFERROR(I51/$G$44,"")
B52: 7 | C52: Insurance | J52: =IFERROR(I52/$G$44,"")
B53: 8 | C53: Audit Costs | J53: =IFERROR(I53/$G$44,"")
B54: 9 | C54: Certifications | J54: =IFERROR(I54/$G$44,"")
...

Sheet COSTING SKU 3
B2: *** This sheet is confidential, please use this to obtain your product cost, but do not share the document. Please print the 'Products & Volume' sheet and the 'Analysis' sheets as a PDF file for the Seedlab team to review ***
B3: Seedlab team members do not need this level of information unless working with you on reducing costs in a private mentor session
B5: PRODUCT | E5: DECLARED WT. | G5: AV. ACTUAL WT. | I5: GIVE AWAY %
B6: ='PRODUCTS & VOLUME'!C25 -> 0 | E6: ='PRODUCTS & VOLUME'!D25 -> 0 | G6: =E6*102.5% -> 0 | I6: =IFERROR((E6-G6)/E6,"")
B8: Ingredients - Batch | H8: KG | I8: % | J8: YIELD | K8: COST/KG | L8: INPUT KG | M8: COST / BATCH
B9: 1 | I9: =IFERROR(IF(H9/$H$29=0,"",H9/$H$29),"") | L9: =IFERROR(H9/J9,"") | M9: =IFERROR(L9*K9,"")
B10: 2 | I10: =IFERROR(IF(H10/$H$29=0,"",H10/$H$29),"") | L10: =IFERROR(H10/J10,"") | M10: =IFERROR(L10*K10,"")
B11: 3 | I11: =IFERROR(IF(H11/$H$29=0,"",H11/$H$29),"") | L11: =IFERROR(H11/J11,"") | M11: =IFERROR(L11*K11,"")
B12: 4 | I12: =IFERROR(IF(H12/$H$29=0,"",H12/$H$29),"") | L12: =IFERROR(H12/J12,"") | M12: =IFERROR(L12*K12,"")
B13: 5 | I13: =IFERROR(IF(H13/$H$29=0,"",H13/$H$29),"") | L13: =IFERROR(H13/J13,"") | M13: =IFERROR(L13*K13,"")
B14: 6 | I14: =IFERROR(IF(H14/$H$29=0,"",H14/$H$29),"") | L14: =IFERROR(H14/J14,"") | M14: =IFERROR(L14*K14,"")
B15: 7 | I15: =IFERROR(IF(H15/$H$29=0,"",H15/$H$29),"") | L15: =IFERROR(H15/J15,"") | M15: =IFERROR(L15*K15,"")
B16: 8 | I16: =IFERROR(IF(H16/$H$29=0,"",H16/$H$29),"") | L16: =IFERROR(H16/J16,"") | M16: =IFERROR(L16*K16,"")
B17: 9 | I17: =IFERROR(IF(H17/$H$29=0,"",H17/$H$29),"") | L17: =IFERROR(H17/J17,"") | M17: =IFERROR(L17*K17,"")
B18: 10 | I18: =IFERROR(IF(H18/$H$29=0,"",H18/$H$29),"") | L18: =IFERROR(H18/J18,"") | M18: =IFERROR(L18*K18,"")
B19: 11 | I19: =IFERROR(IF(H19/$H$29=0,"",H19/$H$29),"") | L19: =IFERROR(H19/J19,"") | M19: =IFERROR(L19*K19,"")
B20: 12 | I20: =IFERROR(IF(H20/$H$29=0,"",H20/$H$29),"") | L20: =IFERROR(H20/J20,"") | M20: =IFERROR(L20*K20,"")
... B28: 20 | I28: =IFERROR(IF(H28/$H$29=0,"",H28/$H$29),"") | L28: =IFERROR(H28/J28,"") | M28: =IFERROR(L28*K28,"")
B29: Total | H29: =SUM(H9:H28) -> 0 | I29: =SUM(I9:I28) -> 0 | L29: =SUM(L9:L28) -> 0 | M29: =SUM(M9:M28) -> 0
B31: Packaging - Batch | H31: EA REQ. | I31: COST/EA | J31: COST/Batch
B32: 1 | J32: =IFERROR(H32*I32,"") -> 0
B33: 2 | J33: =IFERROR(H33*I33,"") -> 0
B34: 3 | J34: =IFERROR(H34*I34,"") -> 0
B35: 4 | J35: =IFERROR(H35*I35,"") -> 0
B36: TOTAL BATCH PACKAGING | J36: =SUM(J32:J35) -> 0
B39: Direct Labour - Batch (includes super, entitlements & work cover) | H39: HEADS | I39: HOURS | J39: RATE/Hr | K39: COST/Batch
B40: 1 | C40: Casual Staff | K40: =H40*I40*J40 -> 0
B41: 2 | C41: Full Time | K41: =H41*I41*J41 -> 0
B42: TOTAL BATCH WAGES | K42: =SUM(K40:K41) -> 0
B44: Total Kilos P/A (As in Sheet 1) | G44: ='PRODUCTS & VOLUME'!M29 -> 0
B45: Overheads - Batch (total annual cost / kg per annum) | I45: ANNUAL | J45: KG/YEAR
B46: 1 | C46: Electricity | J46: =IFERROR(I46/$G$44,"")
B47: 2 | C47: Water | J47: =IFERROR(I47/$G$44,"")
B48: 3 | C48: Rent / Warehousing | J48: =IFERROR(I48/$G$44,"")
B49: 4 | C49: Full Time Admin & Other Staff (incl owners if not included in production) | J49: =IFERROR(I49/$G$44,"")
B50: 5 | C50: Office Supplies | J50: =IFERROR(I50/$G$44,"")
B51: 6 | C51: Production Consumables (gloves, pallet wrap etc) | J51: =IFERROR(I51/$G$44,"")
B52: 7 | C52: Insurance | J52: =IFERROR(I52/$G$44,"")
B53: 8 | C53: Audit Costs | J53: =IFERROR(I53/$G$44,"")
B54: 9 | C54: Certifications | J54: =IFERROR(I54/$G$44,"")
...

Sheet COSTING SKU 4
B2: *** This sheet is confidential, please use this to obtain your product cost, but do not share the document. Please print the 'Products & Volume' sheet and the 'Analysis' sheets as a PDF file for the Seedlab team to review ***
B3: Seedlab team members do not need this level of information unless working with you on reducing costs in a private mentor session
B5: PRODUCT | E5: DECLARED WT. | G5: AV. ACTUAL WT. | I5: GIVE AWAY %
B6: ='PRODUCTS & VOLUME'!C26 -> 0 | E6: ='PRODUCTS & VOLUME'!D26 -> 0 | G6: =E6*102.5% -> 0 | I6: =IFERROR((E6-G6)/E6,"")
B8: Ingredients - Batch | H8: KG | I8: % | J8: YIELD | K8: COST/KG | L8: INPUT KG | M8: COST / BATCH
B9: 1 | I9: =IFERROR(IF(H9/$H$29=0,"",H9/$H$29),"") | L9: =IFERROR(H9/J9,"") | M9: =IFERROR(L9*K9,"")
B10: 2 | I10: =IFERROR(IF(H10/$H$29=0,"",H10/$H$29),"") | L10: =IFERROR(H10/J10,"") | M10: =IFERROR(L10*K10,"")
B11: 3 | I11: =IFERROR(IF(H11/$H$29=0,"",H11/$H$29),"") | L11: =IFERROR(H11/J11,"") | M11: =IFERROR(L11*K11,"")
B12: 4 | I12: =IFERROR(IF(H12/$H$29=0,"",H12/$H$29),"") | L12: =IFERROR(H12/J12,"") | M12: =IFERROR(L12*K12,"")
B13: 5 | I13: =IFERROR(IF(H13/$H$29=0,"",H13/$H$29),"") | L13: =IFERROR(H13/J13,"") | M13: =IFERROR(L13*K13,"")
B14: 6 | I14: =IFERROR(IF(H14/$H$29=0,"",H14/$H$29),"") | L14: =IFERROR(H14/J14,"") | M14: =IFERROR(L14*K14,"")
B15: 7 | I15: =IFERROR(IF(H15/$H$29=0,"",H15/$H$29),"") | L15: =IFERROR(H15/J15,"") | M15: =IFERROR(L15*K15,"")
B16: 8 | I16: =IFERROR(IF(H16/$H$29=0,"",H16/$H$29),"") | L16: =IFERROR(H16/J16,"") | M16: =IFERROR(L16*K16,"")
B17: 9 | I17: =IFERROR(IF(H17/$H$29=0,"",H17/$H$29),"") | L17: =IFERROR(H17/J17,"") | M17: =IFERROR(L17*K17,"")
B18: 10 | I18: =IFERROR(IF(H18/$H$29=0,"",H18/$H$29),"") | L18: =IFERROR(H18/J18,"") | M18: =IFERROR(L18*K18,"")
B19: 11 | I19: =IFERROR(IF(H19/$H$29=0,"",H19/$H$29),"") | L19: =IFERROR(H19/J19,"") | M19: =IFERROR(L19*K19,"")
B20: 12 | I20: =IFERROR(IF(H20/$H$29=0,"",H20/$H$29),"") | L20: =IFERROR(H20/J20,"") | M20: =IFERROR(L20*K20,"")
... B28: 20 | I28: =IFERROR(IF(H28/$H$29=0,"",H28/$H$29),"") | L28: =IFERROR(H28/J28,"") | M28: =IFERROR(L28*K28,"")
B29: Total | H29: =SUM(H9:H28) -> 0 | I29: =SUM(I9:I28) -> 0 | L29: =SUM(L9:L28) -> 0 | M29: =SUM(M9:M28) -> 0
B31: Packaging - Batch | H31: EA REQ. | I31: COST/EA | J31: COST/Batch
B32: 1 | J32: =IFERROR(H32*I32,"") -> 0
B33: 2 | J33: =IFERROR(H33*I33,"") -> 0
B34: 3 | J34: =IFERROR(H34*I34,"") -> 0
B35: 4 | J35: =IFERROR(H35*I35,"") -> 0
B36: TOTAL BATCH PACKAGING | J36: =SUM(J32:J35) -> 0
B39: Direct Labour - Batch (includes super, entitlements & work cover) | H39: HEADS | I39: HOURS | J39: RATE/Hr | K39: COST/Batch
B40: 1 | C40: Casual Staff | K40: =H40*I40*J40 -> 0
B41: 2 | C41: Full Time | K41: =H41*I41*J41 -> 0
B42: TOTAL BATCH WAGES | K42: =SUM(K40:K41) -> 0
B44: Total Kilos P/A (As in Sheet 1) | G44: ='PRODUCTS & VOLUME'!M29 -> 0
B45: Overheads - Batch (total annual cost / kg per annum) | I45: ANNUAL | J45: KG/YEAR
B46: 1 | C46: Electricity | J46: =IFERROR(I46/$G$44,"")
B47: 2 | C47: Water | J47: =IFERROR(I47/$G$44,"")
B48: 3 | C48: Rent / Warehousing | J48: =IFERROR(I48/$G$44,"")
B49: 4 | C49: Full Time Admin & Other Staff (incl owners if not included in production) | J49: =IFERROR(I49/$G$44,"")
B50: 5 | C50: Office Supplies | J50: =IFERROR(I50/$G$44,"")
B51: 6 | C51: Production Consumables (gloves, pallet wrap etc) | J51: =IFERROR(I51/$G$44,"")
B52: 7 | C52: Insurance | J52: =IFERROR(I52/$G$44,"")
B53: 8 | C53: Audit Costs | J53: =IFERROR(I53/$G$44,"")
B54: 9 | C54: Certifications | J54: =IFERROR(I54/$G$44,"")
...

Sheet Costing SKU 5
B2: *** This sheet is confidential, please use this to obtain your product cost, but do not share the document. Please print the 'Products & Volume' sheet and the 'Analysis' sheets as a PDF file for the Seedlab team to review ***
B3: Seedlab team members do not need this level of information unless working with you on reducing costs in a private mentor session
B5: PRODUCT | E5: DECLARED WT. | G5: AV. ACTUAL WT. | I5: GIVE AWAY %
B6: ='PRODUCTS & VOLUME'!C27 -> 0 | E6: ='PRODUCTS & VOLUME'!D27 -> 0 | G6: =E6*102.5% -> 0 | I6: =IFERROR((E6-G6)/E6,"")
B8: Ingredients - Batch | H8: KG | I8: % | J8: YIELD | K8: COST/KG | L8: INPUT KG | M8: COST / BATCH
B9: 1 | I9: =IFERROR(IF(H9/$H$29=0,"",H9/$H$29),"") | L9: =IFERROR(H9/J9,"") | M9: =IFERROR(L9*K9,"")
B10: 2 | I10: =IFERROR(IF(H10/$H$29=0,"",H10/$H$29),"") | L10: =IFERROR(H10/J10,"") | M10: =IFERROR(L10*K10,"")
B11: 3 | I11: =IFERROR(IF(H11/$H$29=0,"",H11/$H$29),"") | L11: =IFERROR(H11/J11,"") | M11: =IFERROR(L11*K11,"")
B12: 4 | I12: =IFERROR(IF(H12/$H$29=0,"",H12/$H$29),"") | L12: =IFERROR(H12/J12,"") | M12: =IFERROR(L12*K12,"")
B13: 5 | I13: =IFERROR(IF(H13/$H$29=0,"",H13/$H$29),"") | L13: =IFERROR(H13/J13,"") | M13: =IFERROR(L13*K13,"")
B14: 6 | I14: =IFERROR(IF(H14/$H$29=0,"",H14/$H$29),"") | L14: =IFERROR(H14/J14,"") | M14: =IFERROR(L14*K14,"")
B15: 7 | I15: =IFERROR(IF(H15/$H$29=0,"",H15/$H$29),"") | L15: =IFERROR(H15/J15,"") | M15: =IFERROR(L15*K15,"")
B16: 8 | I16: =IFERROR(IF(H16/$H$29=0,"",H16/$H$29),"") | L16: =IFERROR(H16/J16,"") | M16: =IFERROR(L16*K16,"")
B17: 9 | I17: =IFERROR(IF(H17/$H$29=0,"",H17/$H$29),"") | L17: =IFERROR(H17/J17,"") | M17: =IFERROR(L17*K17,"")
B18: 10 | I18: =IFERROR(IF(H18/$H$29=0,"",H18/$H$29),"") | L18: =IFERROR(H18/J18,"") | M18: =IFERROR(L18*K18,"")
B19: 11 | I19: =IFERROR(IF(H19/$H$29=0,"",H19/$H$29),"") | L19: =IFERROR(H19/J19,"") | M19: =IFERROR(L19*K19,"")
B20: 12 | I20: =IFERROR(IF(H20/$H$29=0,"",H20/$H$29),"") | L20: =IFERROR(H20/J20,"") | M20: =IFERROR(L20*K20,"")
... B28: 20 | I28: =IFERROR(IF(H28/$H$29=0,"",H28/$H$29),"") | L28: =IFERROR(H28/J28,"") | M28: =IFERROR(L28*K28,"")
B29: Total | H29: =SUM(H9:H28) -> 0 | I29: =SUM(I9:I28) -> 0 | L29: =SUM(L9:L28) -> 0 | M29: =SUM(M9:M28) -> 0
B31: Packaging - Batch | H31: EA REQ. | I31: COST/EA | J31: COST/Batch
B32: 1 | J32: =IFERROR(H32*I32,"") -> 0
B33: 2 | J33: =IFERROR(H33*I33,"") -> 0
B34: 3 | J34: =IFERROR(H34*I34,"") -> 0
B35: 4 | J35: =IFERROR(H35*I35,"") -> 0
B36: TOTAL BATCH PACKAGING | J36: =SUM(J32:J35) -> 0
B39: Direct Labour - Batch (includes super, entitlements & work cover) | H39: HEADS | I39: HOURS | J39: RATE/Hr | K39: COST/Batch
B40: 1 | C40: Casual Staff | K40: =H40*I40*J40 -> 0
B41: 2 | C41: Full Time | K41: =H41*I41*J41 -> 0
B42: TOTAL BATCH WAGES | K42: =SUM(K40:K41) -> 0
B44: Total Kilos P/A (As in Sheet 1) | G44: ='PRODUCTS & VOLUME'!M29 -> 0
B45: Overheads - Batch (total annual cost / kg per annum) | I45: ANNUAL | J45: KG/YEAR
B46: 1 | C46: Electricity | J46: =IFERROR(I46/$G$44,"")
B47: 2 | C47: Water | J47: =IFERROR(I47/$G$44,"")
B48: 3 | C48: Rent / Warehousing | J48: =IFERROR(I48/$G$44,"")
B49: 4 | C49: Full Time Admin & Other Staff (incl owners if not included in production) | J49: =IFERROR(I49/$G$44,"")
B50: 5 | C50: Office Supplies | J50: =IFERROR(I50/$G$44,"")
B51: 6 | C51: Production Consumables (gloves, pallet wrap etc) | J51: =IFERROR(I51/$G$44,"")
B52: 7 | C52: Insurance | J52: =IFERROR(I52/$G$44,"")
B53: 8 | C53: Audit Costs | J53: =IFERROR(I53/$G$44,"")
B54: 9 | C54: Certifications | J54: =IFERROR(I54/$G$44,"")
...

Sheet COSTING SKU 6
B2: *** This sheet is confidential, please use this to obtain your product cost, but do not share the document. Please print the 'Products & Volume' sheet and the 'Analysis' sheets as a PDF file for the Seedlab team to review ***
B3: Seedlab team members do not need this level of information unless working with you on reducing costs in a private mentor session
B5: PRODUCT | E5: DECLARED WT. | G5: AV. ACTUAL WT. | I5: GIVE AWAY %
B6: ='PRODUCTS & VOLUME'!C28 -> 0 | E6: ='PRODUCTS & VOLUME'!D28 -> 0 | G6: =E6*102.5% -> 0 | I6: =IFERROR((E6-G6)/E6,"")
B8: Ingredients - Batch | H8: KG | I8: % | J8: YIELD | K8: COST/KG | L8: INPUT KG | M8: COST / BATCH
B9: 1 | I9: =IFERROR(IF(H9/$H$29=0,"",H9/$H$29),"") | L9: =IFERROR(H9/J9,"") | M9: =IFERROR(L9*K9,"")
B10: 2 | I10: =IFERROR(IF(H10/$H$29=0,"",H10/$H$29),"") | L10: =IFERROR(H10/J10,"") | M10: =IFERROR(L10*K10,"")
B11: 3 | I11: =IFERROR(IF(H11/$H$29=0,"",H11/$H$29),"") | L11: =IFERROR(H11/J11,"") | M11: =IFERROR(L11*K11,"")
B12: 4 | I12: =IFERROR(IF(H12/$H$29=0,"",H12/$H$29),"") | L12: =IFERROR(H12/J12,"") | M12: =IFERROR(L12*K12,"")
B13: 5 | I13: =IFERROR(IF(H13/$H$29=0,"",H13/$H$29),"") | L13: =IFERROR(H13/J13,"") | M13: =IFERROR(L13*K13,"")
B14: 6 | I14: =IFERROR(IF(H14/$H$29=0,"",H14/$H$29),"") | L14: =IFERROR(H14/J14,"") | M14: =IFERROR(L14*K14,"")
B15: 7 | I15: =IFERROR(IF(H15/$H$29=0,"",H15/$H$29),"") | L15: =IFERROR(H15/J15,"") | M15: =IFERROR(L15*K15,"")
B16: 8 | I16: =IFERROR(IF(H16/$H$29=0,"",H16/$H$29),"") | L16: =IFERROR(H16/J16,"") | M16: =IFERROR(L16*K16,"")
B17: 9 | I17: =IFERROR(IF(H17/$H$29=0,"",H17/$H$29),"") | L17: =IFERROR(H17/J17,"") | M17: =IFERROR(L17*K17,"")
B18: 10 | I18: =IFERROR(IF(H18/$H$29=0,"",H18/$H$29),"") | L18: =IFERROR(H18/J18,"") | M18: =IFERROR(L18*K18,"")
B19: 11 | I19: =IFERROR(IF(H19/$H$29=0,"",H19/$H$29),"") | L19: =IFERROR(H19/J19,"") | M19: =IFERROR(L19*K19,"")
B20: 12 | I20: =IFERROR(IF(H20/$H$29=0,"",H20/$H$29),"") | L20: =IFERROR(H20/J20,"") | M20: =IFERROR(L20*K20,"")
... B28: 20 | I28: =IFERROR(IF(H28/$H$29=0,"",H28/$H$29),"") | L28: =IFERROR(H28/J28,"") | M28: =IFERROR(L28*K28,"")
B29: Total | H29: =SUM(H9:H28) -> 0 | I29: =SUM(I9:I28) -> 0 | L29: =SUM(L9:L28) -> 0 | M29: =SUM(M9:M28) -> 0
B31: Packaging - Batch | H31: EA REQ. | I31: COST/EA | J31: COST/Batch
B32: 1 | J32: =IFERROR(H32*I32,"") -> 0
B33: 2 | J33: =IFERROR(H33*I33,"") -> 0
B34: 3 | J34: =IFERROR(H34*I34,"") -> 0
B35: 4 | J35: =IFERROR(H35*I35,"") -> 0
B36: TOTAL BATCH PACKAGING | J36: =SUM(J32:J35) -> 0
B39: Direct Labour - Batch (includes super, entitlements & work cover) | H39: HEADS | I39: HOURS | J39: RATE/Hr | K39: COST/Batch
B40: 1 | C40: Casual Staff | K40: =H40*I40*J40 -> 0
B41: 2 | C41: Full Time | K41: =H41*I41*J41 -> 0
B42: TOTAL BATCH WAGES | K42: =SUM(K40:K41) -> 0
B44: Total Kilos P/A (As in Sheet 1) | G44: ='PRODUCTS & VOLUME'!M29 -> 0
B45: Overheads - Batch (total annual cost / kg per annum) | I45: ANNUAL | J45: KG/YEAR
B46: 1 | C46: Electricity | J46: =IFERROR(I46/$G$44,"")
B47: 2 | C47: Water | J47: =IFERROR(I47/$G$44,"")
B48: 3 | C48: Rent / Warehousing | J48: =IFERROR(I48/$G$44,"")
B49: 4 | C49: Full Time Admin & Other Staff (incl owners if not included in production) | J49: =IFERROR(I49/$G$44,"")
B50: 5 | C50: Office Supplies | J50: =IFERROR(I50/$G$44,"")
B51: 6 | C51: Production Consumables (gloves, pallet wrap etc) | J51: =IFERROR(I51/$G$44,"")
B52: 7 | C52: Insurance | J52: =IFERROR(I52/$G$44,"")
B53: 8 | C53: Audit Costs | J53: =IFERROR(I53/$G$44,"")
B54: 9 | C54: Certifications | J54: =IFERROR(I54/$G$44,"")
...

Sheet ANALYSIS
A1: Analysis
C2: Once complete, please click the PRINT button and save as PDF for sharing with the Seedlab team.
B7: ='PRODUCTS & VOLUME'!B23 -> 1. | C7: PRODUCT PRICING REVIEW | U7: ='PRODUCTS & VOLUME'!B26 -> 4. | V7: PRODUCT PRICING REVIEW
D9: PACK | F9: UNIT | H9: EX | J9: RSP | L9: Unit Price | O9: Standard | P9: Deep Cut | Q9: Promotion | W9: PACK | Y9: UNIT | AA9: EX | AC9: RSP | AE9: Unit Price | AH9: Standard | AI9: Deep Cut | AJ9: Promotion
C10: PRODUCTS | D10: SIZE | E10: RRP | F10: PRICING | G10: GST | H10: GST | J10: Difference | L10: Difference | O10: Promotion | P10: Promotion | Q10: Frequency | V10: PRODUCTS | W10: SIZE | X10: RRP | Y10: PRICING | Z10: GST | AA10: GST | AC10: Difference | AE10: Difference | AH10: Promotion | AI10: Promotion | AJ10: Frequency
C11: =IF('PRODUCTS & VOLUME'!C23="","",'PRODUCTS & VOLUME'!C23) | D11: =IF('PRODUCTS & VOLUME'!D23="","",'PRODUCTS & VOLUME'!D23) | E11: ='PRODUCTS & VOLUME'!J23 -> 0 | F11: ='PRODUCTS & VOLUME'!L23 | G11: =IF('PRODUCTS & VOLUME'!K23="","",'PRODUCTS & VOLUME'!K23) | H11: =IF(G11="YES",(E11/110%),E11) -> 0 | V11: =IF('PRODUCTS & VOLUME'!C26="","",'PRODUCTS & VOLUME'!C26) | W11: =IF('PRODUCTS & VOLUME'!D26="","",'PRODUCTS & VOLUME'!D26) | X11: ='PRODUCTS & VOLUME'!AC23 -> 0 | Y11: ='PRODUCTS & VOLUME'!J26 -> 0 | Z11: =IF('PRODUCTS & VOLUME'!K26="","",'PRODUCTS & VOLUME'!K26) | AA11: =IF(Z11="YES",(X11/110%),X11) -> 0
C12: Nearest Competitor (Woolworths) | F12: =IFERROR(E12/D12,"") | H12: =IF(G12="YES",(E12/110%),E12) -> 0 | J12: =E11-E12 -> 0 | K12: =IFERROR((E11-E12)/E11,"") | L12: =IFERROR(F11-F12,"") | M12: =IFERROR((F11-F12)/F11,"") | V12: Nearest Competitor (Woolworths) | Y12: =IFERROR(X12/W12,"") | AA12: =IF(Z12="YES",(X12/110%),X12) -> 0 | AC12: =X11-X12 -> 0 | AD12: =IFERROR((X11-X12)/X11,"") | AE12: =IFERROR(Y11-Y12,"") | AF12: =IFERROR((Y11-Y12)/Y11,"")
C13: Cheapest Competitor (Woolworths) | F13: =IFERROR(E13/D13,"") | H13: =IF(G13="YES",(E13/110%),E13) -> 0 | J13: =E11-E13 -> 0 | K13: =IFERROR((E11-E13)/E12,"") | L13: =IFERROR(F11-F13,"") | M13: =IFERROR((F11-F13)/F12,"") | V13: Cheapest Competitor (Woolworths) | Y13: =IFERROR(X13/W13,"") | AA13: =IF(Z13="YES",(X13/110%),X13) -> 0 | AC13: =X11-X13 -> 0 | AD13: =IFERROR((X11-X13)/X12,"") | AE13: =IFERROR(Y11-Y13,"") | AF13: =IFERROR((Y11-Y13)/Y12,"")
C15: CUSTOMER MARGIN REVIEW | D15: Woolworths | E15: Other Retail (Average) | F15: Other (Direct To Customer) | H15: Notes on this product: | V15: CUSTOMER MARGIN REVIEW | W15: Woolworths | X15: Other Retail (Average) | Y15: Other (Direct To Customer) | AA15: Notes on this product:
B16: TOP DOWN | C16: Retailer Actual Sell Price | U16: TOP DOWN | V16: Retailer Actual Sell Price
C17: Retailer / Consumer Buy Price | V17: Retailer / Consumer Buy Price
C18: Rebates (Collective) | V18: Rebates (Collective)
C19: Retailer Net Buy Price | D19: =D17-D18 -> 0 | E19: =E17-E18 -> 0 | F19: 0 | V19: Retailer Net Buy Price | W19: =W17-W18 -> 0 | X19: =X17-X18 -> 0 | Y19: 0
C20: Retailer Margin | D20: =IFERROR((D16-D19)/D16,"") | E20: =IFERROR((E16-E19)/E16,"") | F20: N/A | V20: Retailer Margin | W20: =IFERROR((W16-W19)/W16,"") | X20: =IFERROR((X16-X19)/X16,"") | Y20: N/A
C22: Category Expectations | V22: Category Expectations
C23: Gap % | D23: =IFERROR(D20-D22,"") | E23: =IFERROR(E20-E22,"") | V23: Gap % | W23: =IFERROR(W20-W22,"") | X23: =IFERROR(X20-X22,"")
C24: Gap $ | D24: =IFERROR((D19*D22)-(D19*D20),"") | E24: =IFERROR((E19*E22)-(E19*E20),"") | V24: Gap $ | W24: =IFERROR((W19*W22)-(W19*W20),"") | X24: =IFERROR((X19*X22)-(X19*X20),"")
B26: BOTTOM UP | C26: Target Sell Price | D26: =IFERROR(D19-D24,"") | E26: =IFERROR(E19-E24,"") | H26: QUESTIONS FOR CONSIDERATION: | U26: BOTTOM UP | V26: Target Sell Price | W26: =IFERROR(W19-W24,"") | X26: =IFERROR(X19-X24,"") | AA26: QUESTIONS FOR CONSIDERATION:
C27: New Margin $ | D27: =IFERROR(D26-D32,"") | E27: =IFERROR(E26-E32,"") | H27: On comparing your RSP & Unit Pricing, is an adjustment required for this product in order to be competitive? | V27: New Margin $ | W27: =IFERROR(W26-W32,"") | X27: =IFERROR(X26-X32,"") | AA27: On comparing your RSP & Unit Pricing, is an adjustment required for this product in order to be competitive?
C28: New Margin % | D28: =IFERROR((D26-D32)/D26,"") | E28: =IFERROR((E26-E32)/E26,"") | H28: If so, what does this do to your margins? | V28: New Margin % | W28: =IFERROR((W26-W32)/W26,"") | X28: =IFERROR((X26-X32)/X26,"") | AA28: If so, what does this do to your margins?
H29: Where can savings be made to COGS? Consider big wins first. | AA29: Where can savings be made to COGS? Consider big wins first.
C30: Current Margin % | D30: =IFERROR((D19-D32)/D19,"") | E30: =IFERROR((E19-E32)/E19,"") | F30: =IFERROR((F17-F32)/F17,"") | H30: If your overheads make your product non-proffitable, what needs to happen to change it? | V30: Current Margin % | W30: =IFERROR((W19-W32)/W19,"") | X30: =IFERROR((X19-X32)/X19,"") | Y30: =IFERROR((Y17-Y32)/Y17,"") | AA30: If your overheads make your product non-proffitable, what needs to happen to change it?
C31: Current Margin $ | D31: =D19-D32 -> 0 | E31: =E19-E32 -> 0 | F31: =F17-F32 -> 0 | H31: What are the risks associated with your current distribution / sales spread? | V31: Current Margin $ | W31: =W19-W32 -> 0 | X31: =X19-X32 -> 0 | Y31: =Y17-Y32 -> 0 | AA31: What are the risks associated with your current distribution / sales spread?
C32: Current Cost | V32: Current Cost
C34: Current Volume | V34: Current Volume
C35: Current Value | V35: Current Value
B40: ='PRODUCTS & VOLUME'!B24 -> 2. | C40: PRODUCT PRICING REVIEW | U40: ='PRODUCTS & VOLUME'!B27 -> 5. | V40: PRODUCT PRICING REVIEW
D42: PACK | F42: UNIT | H42: EX | J42: RSP | L42: Unit Price | O42: Standard | P42: Deep Cut | Q42: Promotion | W42: PACK | Y42: UNIT | AA42: EX | AC42: RSP | AE42: Unit Price | AH42: Standard | AI42: Deep Cut | AJ42: Promotion
C43: PRODUCTS | D43: SIZE | E43: RRP | F43: PRICING | G43: GST | H43: GST | J43: Difference | L43: Difference | O43: Promotion | P43: Promotion | Q43: Frequency | V43: PRODUCTS | W43: SIZE | X43: RRP | Y43: PRICING | Z43: GST | AA43: GST | AC43: Difference | AE43: Difference | AH43: Promotion | AI43: Promotion | AJ43: Frequency
C44: =IF('PRODUCTS & VOLUME'!C24="","",'PRODUCTS & VOLUME'!C24) | D44: =IF('PRODUCTS & VOLUME'!D24="","",'PRODUCTS & VOLUME'!D24) | E44: ='PRODUCTS & VOLUME'!J24 -> 0 | F44: ='PRODUCTS & VOLUME'!L24 | G44: =IF('PRODUCTS & VOLUME'!K24="","",'PRODUCTS & VOLUME'!K24) | H44: =IF(G44="YES",(E44/110%),E44) -> 0 | V44: =IF('PRODUCTS & VOLUME'!C27="","",'PRODUCTS & VOLUME'!C27) | W44: =IF('PRODUCTS & VOLUME'!D27="","",'PRODUCTS & VOLUME'!D27) | X44: ='PRODUCTS & VOLUME'!J27 -> 0 | Y44: ='PRODUCTS & VOLUME'!L27 | Z44: =IF('PRODUCTS & VOLUME'!K27="","",'PRODUCTS & VOLUME'!K27) | AA44: =IF(Z44="YES",(X44/110%),X44) -> 0
C45: Nearest Competitor (Woolworths) | F45: =IFERROR(E45/D45,"") | H45: =IF(G45="YES",(E45/110%),E45) -> 0 | J45: =E44-E45 -> 0 | K45: =IFERROR((E44-E45)/E44,"") | L45: =IFERROR(F44-F45,"") | M45: =IFERROR((F44-F45)/F44,"") | V45: Nearest Competitor (Woolworths) | Y45: =IFERROR(X45/W45,"") | AA45: =IF(Z45="YES",(X45/110%),X45) -> 0 | AC45: =X44-X45 -> 0 | AD45: =IFERROR((X44-X45)/X44,"") | AE45: =IFERROR(Y44-Y45,"") | AF45: =IFERROR((Y44-Y45)/Y44,"")
C46: Cheapest Competitor (Woolworths) | F46: =IFERROR(E46/D46,"") | H46: =IF(G46="YES",(E46/110%),E46) -> 0 | J46: =E44-E46 -> 0 | K46: =IFERROR((E44-E46)/E45,"") | L46: =IFERROR(F44-F46,"") | M46: =IFERROR((F44-F46)/F45,"") | V46: Cheapest Competitor (Woolworths) | Y46: =IFERROR(X46/W46,"") | AA46: =IF(Z46="YES",(X46/110%),X46) -> 0 | AC46: =X44-X46 -> 0 | AD46: =IFERROR((X44-X46)/X45,"") | AE46: =IFERROR(Y44-Y46,"") | AF46: =IFERROR((Y44-Y46)/Y45,"")
C48: CUSTOMER MARGIN REVIEW | D48: Woolworths | E48: Other Retail (Average) | F48: Other (Direct To Customer) | H48: Notes on this product: | V48: CUSTOMER MARGIN REVIEW | W48: Woolworths | X48: Other Retail (Average) | Y48: Other (Direct To Customer) | AA48: Notes on this product:
B49: TOP DOWN | C49: Retailer Actual Sell Price | U49: TOP DOWN | V49: Retailer Actual Sell Price
C50: Retailer / Consumer Buy Price | V50: Retailer / Consumer Buy Price
C51: Rebates (Collective) | V51: Rebates (Collective)
C52: Retailer Net Buy Price | D52: =D50-D51 -> 0 | E52: =E50-E51 -> 0 | F52: 0 | V52: Retailer Net Buy Price | W52: =W50-W51 -> 0 | X52: =X50-X51 -> 0 | Y52: 0
C53: Retailer Margin | D53: =IFERROR((D49-D52)/D49,"") | E53: =IFERROR((E49-E52)/E49,"") | F53: N/A | V53: Retailer Margin | W53: =IFERROR((W49-W52)/W49,"") | X53: =IFERROR((X49-X52)/X49,"") | Y53: N/A
C55: Category Expectations | V55: Category Expectations
C56: Gap % | D56: =IFERROR(D53-D55,"") | E56: =IFERROR(E53-E55,"") | V56: Gap % | W56: =IFERROR(W53-W55,"") | X56: =IFERROR(X53-X55,"")
...

Sheet LISTS
B3: YES
B4: NO
